Workbook

Sheet ReadMe
A1: Operational Sense - Equipment Hierarchy Proposal (DRAFT v0.1)
A2: Group 1 - Industrial Knowledge Base. Built from Operational_Sense_Industrial_Knowledge_Base_g1.xlsx (Failure_Mode_Taxonomy, Taxonomy_Proposed, Import_View).
A4: Status
A5: Status | B5: DRAFT proposal for team review. Nothing here is approved by M01/M02 or by Groups 2 and 3.
A6: Source data | B6: Rows marked 'In taxonomy' come from Failure_Mode_Taxonomy. Rows marked 'Proposed (not approved)' come from Taxonomy_Proposed (11 cases with no taxonomy entry). Merge proposals for subsystems are this sheet's own suggestion; see Open_Issues.
A7: No new engineering content | B7: Descriptions are copied from the source workbook. Cases are synthetic; no OEM manual or practitioner review is behind them.
A9: Sheets
A10: Summary | B10: Counts per class and integrity checks (formulas).
A11: Hierarchy | B11: All nodes, levels 1-5, with parent_id. Load this for the parent-child structure.
A12: Component_Map | B12: One row per component + failure mode, with taxonomy code, status and linked case count (formula).
A13: Case_Link | B13: Each of the 50 cases linked to its component through the taxonomy code (formula lookup).
A14: Open_Issues | B14: Decisions the team must take before this is final.
A16: Hierarchy levels
A17: Level | B17: Operational Sense name | C17: Nearest ISO 14224 concept (from memory - VERIFY against the standard)
A18: 1 | B18: Equipment class (EQ-PUMP, EQ-MOTOR, EQ-COMP) | C18: Equipment class
A19: 2 | B19: Equipment type (TY-...) | C19: Equipment type within the class
A20: 3 | B20: Subsystem (SS-...) | C20: Subunit
A21: 4 | B21: Component (CP-...) | C21: Component / maintainable item
A22: 5 | B22: Failure mode (MD-...) | C22: Attribute of a failure record, not a hierarchy level in ISO; shown as a leaf so it can be filtered
A24: ID conventions
A25: Class | B25: EQ-<CLASS> | C25: Existing IDs, unchanged (already used as equipment_class_id).
A26: Type / subsystem / component | B26: TY-<CLASS>-<TYPE>, SS-<CLASS>-<SUB>, CP-<CLASS>-<SUB>-<nn> | C26: New IDs proposed here.
A27: Failure mode | B27: MD-<CLASS>-<SUB>-<nn>-<nn> | C27: Prefix MD- chosen on purpose so it never clashes with the project-local FM-xxx vocabulary IDs.
A28: Taxonomy code | B28: Kept exactly as in the source workbook (e.g. PUMP.BRNG.ROLL, ELEC.MOT.STAT). | C28: Pattern is inconsistent between pumps/compressors and motors; see Open_Issues #3.
A30: Legend
A31: Amber fill | B31: Proposed (not approved) - comes from Taxonomy_Proposed or is a new subsystem.
A32: Blue / green fill | B32: Class / type rows in the Hierarchy sheet.

Sheet Summary
A1: Summary (all values are formulas on the Hierarchy / Case_Link sheets)
A3: Class | B3: class_id | C3: Subsystems | D3: Components | E3: of which proposed | F3: Failure modes | G3: Cases linked
A4: Pump | B4: EQ-PUMP | C4: =COUNTIFS(Hierarchy!$F$2:$F$115,B4,Hierarchy!$C$2:$C$115,3) -> 6 | D4: =COUNTIFS(Hierarchy!$F$2:$F$115,B4,Hierarchy!$C$2:$C$115,4) -> 13 | E4: =COUNTIFS(Hierarchy!$F$2:$F$115,B4,Hierarchy!$C$2:$C$115,4,Hierarchy!$J$2:$J$115,"Proposed*") -> 3 | F4: =COUNTIFS(Hierarchy!$F$2:$F$115,B4,Hierarchy!$C$2:$C$115,5) -> 13 | G4: =COUNTIF(Case_Link!$B$2:$B$51,B4) -> 17
A5: Electric Motor | B5: EQ-MOTOR | C5: =COUNTIFS(Hierarchy!$F$2:$F$115,B5,Hierarchy!$C$2:$C$115,3) -> 10 | D5: =COUNTIFS(Hierarchy!$F$2:$F$115,B5,Hierarchy!$C$2:$C$115,4) -> 14 | E5: =COUNTIFS(Hierarchy!$F$2:$F$115,B5,Hierarchy!$C$2:$C$115,4,Hierarchy!$J$2:$J$115,"Proposed*") -> 4 | F5: =COUNTIFS(Hierarchy!$F$2:$F$115,B5,Hierarchy!$C$2:$C$115,5) -> 14 | G5: =COUNTIF(Case_Link!$B$2:$B$51,B5) -> 17
A6: Compressor | B6: EQ-COMP | C6: =COUNTIFS(Hierarchy!$F$2:$F$115,B6,Hierarchy!$C$2:$C$115,3) -> 10 | D6: =COUNTIFS(Hierarchy!$F$2:$F$115,B6,Hierarchy!$C$2:$C$115,4) -> 14 | E6: =COUNTIFS(Hierarchy!$F$2:$F$115,B6,Hierarchy!$C$2:$C$115,4,Hierarchy!$J$2:$J$115,"Proposed*") -> 4 | F6: =COUNTIFS(Hierarchy!$F$2:$F$115,B6,Hierarchy!$C$2:$C$115,5) -> 14 | G6: =COUNTIF(Case_Link!$B$2:$B$51,B6) -> 16
A7: Total | C7: =SUM(C4:C6) -> 26 | D7: =SUM(D4:D6) -> 41 | E7: =SUM(E4:E6) -> 11 | F7: =SUM(F4:F6) -> 41 | G7: =SUM(G4:G6) -> 50
A10: Integrity checks (expected result in column C)
A11: Nodes whose parent_id does not exist | B11: =SUMPRODUCT((Hierarchy!$B$2:$B$115<>"")*(COUNTIF(Hierarchy!$A$2:$A$115,Hierarchy!$B$2:$B$115)=0)) -> 0 | C11: 0 | D11: =IF(C11="info","info",IF(B11=C11,"PASS","FAIL")) -> PASS
A12: Duplicate node_id values | B12: =SUMPRODUCT(--(COUNTIF(Hierarchy!$A$2:$A$115,Hierarchy!$A$2:$A$115)>1)) -> 0 | C12: 0 | D12: =IF(C12="info","info",IF(B12=C12,"PASS","FAIL")) -> PASS
A13: Duplicate taxonomy codes (components) | B13: =SUMPRODUCT(--(COUNTIF(Component_Map!$H$2:$H$42,Component_Map!$H$2:$H$42)>1)) -> 0 | C13: 0 | D13: =IF(C13="info","info",IF(B13=C13,"PASS","FAIL")) -> PASS
A14: Cases not linked to a component | B14: =COUNTIF(Case_Link!$H$2:$H$51,"UNMAPPED") -> 0 | C14: 0 | D14: =IF(C14="info","info",IF(B14=C14,"PASS","FAIL")) -> PASS
A15: Components with no linked case | B15: =COUNTIF(Component_Map!$M$2:$M$42,0) -> 0 | C15: info | D15: =IF(C15="info","info",IF(B15=C15,"PASS","FAIL")) -> info
A17: Components with no linked case is informational. Today every component has at least one case, so any component added later without a case will show up here.

Sheet Hierarchy
A1: node_id | B1: parent_id | C1: level | D1: level_name | E1: node_name | F1: class_id | G1: subsystem_id | H1: taxonomy_code | I1: iso_fm_code_candidate (VERIFY) | J1: status | K1: source_subsystem | L1: source_component | M1: description (from source) | N1: note
A2: EQ-PUMP | C2: 1 | D2: Equipment class | E2: Pump | F2: EQ-PUMP | J2: In taxonomy | N2: Class ID already used as equipment_class_id in Import_View.
A3: TY-PUMP-CENT | B3: EQ-PUMP | C3: 2 | D3: Equipment type | E3: Centrifugal pump | F3: EQ-PUMP | J3: In taxonomy | N3: Workbook currently labels this as 'Equipment Class'.
A4: SS-PUMP-BRNG | B4: TY-PUMP-CENT | C4: 3 | D4: Subsystem | E4: Bearing Assembly | F4: EQ-PUMP | G4: SS-PUMP-BRNG | J4: In taxonomy | K4: Bearing Assembly
A5: CP-PUMP-BRNG-01 | B5: SS-PUMP-BRNG | C5: 4 | D5: Component | E5: Rolling Element Bearing | F5: EQ-PUMP | G5: SS-PUMP-BRNG | H5: PUMP.BRNG.ROLL | J5: In taxonomy | K5: Bearing Assembly | L5: Rolling Element Bearing
A6: MD-PUMP-BRNG-01-01 | B6: CP-PUMP-BRNG-01 | C6: 5 | D6: Failure mode | E6: Bearing Wear | F6: EQ-PUMP | G6: SS-PUMP-BRNG | H6: PUMP.BRNG.ROLL | I6: VIB | J6: In taxonomy | K6: Bearing Assembly | L6: Rolling Element Bearing | M6: Progressive spalling and pitting of raceways and rolling elements under cyclic contact stress, increasing internal clearance and friction.
A7: CP-PUMP-BRNG-02 | B7: SS-PUMP-BRNG | C7: 4 | D7: Component | E7: Bearing Housing Isolators / Lip Seals | F7: EQ-PUMP | G7: SS-PUMP-BRNG | H7: PUMP.BRNG.SEAL | J7: In taxonomy | K7: Bearing Assembly | L7: Bearing Housing Isolators / Lip Seals
A8: MD-PUMP-BRNG-02-01 | B8: CP-PUMP-BRNG-02 | C8: 5 | D8: Failure mode | E8: Bearing Housing Seal Failure | F8: EQ-PUMP | G8: SS-PUMP-BRNG | H8: PUMP.BRNG.SEAL | I8: ELU | J8: In taxonomy | K8: Bearing Assembly | L8: Bearing Housing Isolators / Lip Seals | M8: Worn lip seals or isolators let lubricant escape and let dust or moisture enter the bearing housing.
A9: SS-PUMP-SEAL | B9: TY-PUMP-CENT | C9: 3 | D9: Subsystem | E9: Mechanical Seal | F9: EQ-PUMP | G9: SS-PUMP-SEAL | J9: In taxonomy | K9: Mechanical Seal
A10: CP-PUMP-SEAL-01 | B10: SS-PUMP-SEAL | C10: 4 | D10: Component | E10: Seal Faces (Rotating / Stationary) | F10: EQ-PUMP | G10: SS-PUMP-SEAL | H10: PUMP.SEAL.FACE | J10: In taxonomy | K10: Mechanical Seal | L10: Seal Faces (Rotating / Stationary)
A11: MD-PUMP-SEAL-01-01 | B11: CP-PUMP-SEAL-01 | C11: 5 | D11: Failure mode | E11: Seal Face Leakage | F11: EQ-PUMP | G11: SS-PUMP-SEAL | H11: PUMP.SEAL.FACE | I11: ELP | J11: In taxonomy | K11: Mechanical Seal | L11: Seal Faces (Rotating / Stationary) | M11: Loss of lapped seal-face contact through wear, thermal cracking, dry running or elastomer hardening, allowing process fluid to escape along the shaft.
A12: SS-PUMP-HYDR | B12: TY-PUMP-CENT | C12: 3 | D12: Subsystem | E12: Hydraulic End | F12: EQ-PUMP | G12: SS-PUMP-HYDR | J12: In taxonomy | K12: Hydraulic End
A13: CP-PUMP-HYDR-01 | B13: SS-PUMP-HYDR | C13: 4 | D13: Component | E13: Impeller | F13: EQ-PUMP | G13: SS-PUMP-HYDR | H13: PUMP.HYDR.IMPL | J13: In taxonomy | K13: Hydraulic End | L13: Impeller
A14: MD-PUMP-HYDR-01-01 | B14: CP-PUMP-HYDR-01 | C14: 5 | D14: Failure mode | E14: Cavitation | F14: EQ-PUMP | G14: SS-PUMP-HYDR | H14: PUMP.HYDR.IMPL | I14: NOI | J14: In taxonomy | K14: Hydraulic End | L14: Impeller | M14: Vapour bubbles form when local pressure falls below fluid vapour pressure and collapse violently on impeller surfaces, causing pitting and pressure pulsation.
A15: CP-PUMP-HYDR-02 | B15: SS-PUMP-HYDR | C15: 4 | D15: Component | E15: Impeller and Wear Rings | F15: EQ-PUMP | G15: SS-PUMP-HYDR | H15: PUMP.HYDR.WEAR | J15: In taxonomy | K15: Hydraulic End | L15: Impeller and Wear Rings
A16: MD-PUMP-HYDR-02-01 | B16: CP-PUMP-HYDR-02 | C16: 5 | D16: Failure mode | E16: Impeller / Wear Ring Wear | F16: EQ-PUMP | G16: SS-PUMP-HYDR | H16: PUMP.HYDR.WEAR | I16: LOO | J16: In taxonomy | K16: Hydraulic End | L16: Impeller and Wear Rings | M16: Erosion or corrosion of vane tips and growth of wear-ring clearance, creating internal recirculation and reduced hydraulic efficiency.
A17: CP-PUMP-HYDR-03 | B17: SS-PUMP-HYDR | C17: 4 | D17: Component | E17: Impeller and Casing Volute | F17: EQ-PUMP | G17: SS-PUMP-HYDR | H17: PUMP.HYDR.RECR | J17: In taxonomy | K17: Hydraulic End | L17: Impeller and Casing Volute
A18: MD-PUMP-HYDR-03-01 | B18: CP-PUMP-HYDR-03 | C18: 5 | D18: Failure mode | E18: Low-Flow Recirculation | F18: EQ-PUMP | G18: SS-PUMP-HYDR | H18: PUMP.HYDR.RECR | I18: VIB | J18: In taxonomy | K18: Hydraulic End | L18: Impeller and Casing Volute | M18: Operation well below best efficiency flow produces flow separation and recirculation at impeller inlet and outlet, causing pressure pulsation and radial load.
A19: CP-PUMP-HYDR-04 | B19: SS-PUMP-HYDR | C19: 4 | D19: Component | E19: Impeller Flow Passage | F19: EQ-PUMP | G19: SS-PUMP-HYDR | H19: PUMP.HYDR.BLKG | J19: Proposed (not approved) | K19: Hydraulic End | L19: Impeller Flow Passage
A20: MD-PUMP-HYDR-04-01 | B20: CP-PUMP-HYDR-04 | C20: 5 | D20: Failure mode | E20: Impeller Passage Blockage (Foreign Material) | F20: EQ-PUMP | G20: SS-PUMP-HYDR | H20: PUMP.HYDR.BLKG | I20: PLU | J20: Proposed (not approved) | K20: Hydraulic End | L20: Impeller Flow Passage
A21: CP-PUMP-HYDR-05 | B21: SS-PUMP-HYDR | C21: 4 | D21: Component | E21: Pump-System Duty Point | F21: EQ-PUMP | G21: SS-PUMP-HYDR | H21: PUMP.HYDR.RNOT | J21: Proposed (not approved) | K21: Hydraulic End | L21: Pump-System Duty Point
A22: MD-PUMP-HYDR-05-01 | B22: CP-PUMP-HYDR-05 | C22: 5 | D22: Failure mode | E22: Operation Far Right of Duty Point (High-Flow Runout) | F22: EQ-PUMP | G22: SS-PUMP-HYDR | H22: PUMP.HYDR.RNOT | I22: HIO | J22: Proposed (not approved) | K22: Hydraulic End | L22: Pump-System Duty Point
A23: SS-PUMP-DRVT | B23: TY-PUMP-CENT | C23: 3 | D23: Subsystem | E23: Drive Train | F23: EQ-PUMP | G23: SS-PUMP-DRVT | J23: In taxonomy | K23: Drive Train
A24: CP-PUMP-DRVT-01 | B24: SS-PUMP-DRVT | C24: 4 | D24: Component | E24: Flexible Coupling | F24: EQ-PUMP | G24: SS-PUMP-DRVT | H24: PUMP.DRVT.CPLG | J24: In taxonomy | K24: Drive Train | L24: Flexible Coupling
A25: MD-PUMP-DRVT-01-01 | B25: CP-PUMP-DRVT-01 | C25: 5 | D25: Failure mode | E25: Coupling Misalignment | F25: EQ-PUMP | G25: SS-PUMP-DRVT | H25: PUMP.DRVT.CPLG | I25: VIB | J25: In taxonomy | K25: Drive Train | L25: Flexible Coupling | M25: Angular or parallel offset between pump and driver shafts imposing cyclic loads on coupling elements, bearings and seals.
A26: CP-PUMP-DRVT-02 | B26: SS-PUMP-DRVT | C26: 4 | D26: Component | E26: Pump Rotating Assembly / Motor Protection | F26: EQ-PUMP | G26: SS-PUMP-DRVT | H26: PUMP.DRVT.OVLD | J26: Proposed (not approved) | K26: Drive Train | L26: Pump Rotating Assembly / Motor Protection
A27: MD-PUMP-DRVT-02-01 | B27: CP-PUMP-DRVT-02 | C27: 5 | D27: Failure mode | E27: Mechanical Overload or Binding Causing Protective Trip | F27: EQ-PUMP | G27: SS-PUMP-DRVT | H27: PUMP.DRVT.OVLD | I27: UST | J27: Proposed (not approved) | K27: Drive Train | L27: Pump Rotating Assembly / Motor Protection
A28: SS-PUMP-SUCT | B28: TY-PUMP-CENT | C28: 3 | D28: Subsystem | E28: Suction System | F28: EQ-PUMP | G28: SS-PUMP-SUCT | J28: In taxonomy | K28: Suction Line + Suction and Priming | N28: Merge proposal: combines source subsystems Suction Line + Suction and Priming.
A29: CP-PUMP-SUCT-01 | B29: SS-PUMP-SUCT | C29: 4 | D29: Component | E29: Suction Strainer | F29: EQ-PUMP | G29: SS-PUMP-SUCT | H29: PUMP.SUCT.STRN | J29: In taxonomy | K29: Suction Line | L29: Suction Strainer
A30: MD-PUMP-SUCT-01-01 | B30: CP-PUMP-SUCT-01 | C30: 5 | D30: Failure mode | E30: Strainer Blockage | F30: EQ-PUMP | G30: SS-PUMP-SUCT | H30: PUMP.SUCT.STRN | I30: PLU | J30: In taxonomy | K30: Suction Line | L30: Suction Strainer | M30: Debris accumulation restricts suction flow and lowers pump inlet pressure.
A31: CP-PUMP-SUCT-02 | B31: SS-PUMP-SUCT | C31: 4 | D31: Component | E31: Suction Line Joints and Gland Seal Interface | F31: EQ-PUMP | G31: SS-PUMP-SUCT | H31: PUMP.SUCT.PRIM | J31: In taxonomy | K31: Suction and Priming | L31: Suction Line Joints and Gland Seal Interface
A32: MD-PUMP-SUCT-02-01 | B32: CP-PUMP-SUCT-02 | C32: 5 | D32: Failure mode | E32: Air Ingress / Loss of Prime | F32: EQ-PUMP | G32: SS-PUMP-SUCT | H32: PUMP.SUCT.PRIM | I32: LOO | J32: In taxonomy | K32: Suction and Priming | L32: Suction Line Joints and Gland Seal Interface | M32: Air drawn through leaking suction joints or seal interface collects at the impeller eye, breaking the liquid column (gas binding).
A33: SS-PUMP-SHFT | B33: TY-PUMP-CENT | C33: 3 | D33: Subsystem | E33: Shaft Assembly | F33: EQ-PUMP | G33: SS-PUMP-SHFT | J33: In taxonomy | K33: Shaft Assembly
A34: CP-PUMP-SHFT-01 | B34: SS-PUMP-SHFT | C34: 4 | D34: Component | E34: Pump Shaft | F34: EQ-PUMP | G34: SS-PUMP-SHFT | H34: PUMP.SHFT.SHAF | J34: In taxonomy | K34: Shaft Assembly | L34: Pump Shaft
A35: MD-PUMP-SHFT-01-01 | B35: CP-PUMP-SHFT-01 | C35: 5 | D35: Failure mode | E35: Shaft Fatigue Fracture | F35: EQ-PUMP | G35: SS-PUMP-SHFT | H35: PUMP.SHFT.SHAF | I35: STD | J35: In taxonomy | K35: Shaft Assembly | L35: Pump Shaft | M35: Crack initiation at stress raisers (keyway, step, sleeve end) under rotating bending, then propagation to fracture.
A36: EQ-MOTOR | C36: 1 | D36: Equipment class | E36: Electric Motor | F36: EQ-MOTOR | J36: In taxonomy | N36: Class ID already used as equipment_class_id in Import_View.
A37: TY-MOTOR-IND | B37: EQ-MOTOR | C37: 2 | D37: Equipment type | E37: Three-phase induction motor | F37: EQ-MOTOR | J37: In taxonomy | N37: Workbook currently labels this as 'Equipment Class'.
A38: SS-MOT-STAT | B38: TY-MOTOR-IND | C38: 3 | D38: Subsystem | E38: Stator and Windings | F38: EQ-MOTOR | G38: SS-MOT-STAT | J38: In taxonomy | K38: Stator & Windings
A39: CP-MOT-STAT-01 | B39: SS-MOT-STAT | C39: 4 | D39: Component | E39: Winding Insulation (Copper Magnet Wire and Varnish) | F39: EQ-MOTOR | G39: SS-MOT-STAT | H39: ELEC.MOT.STAT | J39: In taxonomy | K39: Stator & Windings | L39: Winding Insulation (Copper Magnet Wire and Varnish)
A40: MD-MOT-STAT-01-01 | B40: CP-MOT-STAT-01 | C40: 5 | D40: Failure mode | E40: Insulation Breakdown | F40: EQ-MOTOR | G40: SS-MOT-STAT | H40: ELEC.MOT.STAT | I40: BRD | J40: In taxonomy | K40: Stator & Windings | L40: Winding Insulation (Copper Magnet Wire and Varnish) | M40: Thermal, electrical or contamination-driven degradation of winding insulation leading to turn-to-turn, phase-to-phase or ground faults.
...

Sheet Component_Map
A1: component_id | B1: failure_mode_id | C1: class_id | D1: equipment_type | E1: subsystem_id | F1: subsystem | G1: component | H1: taxonomy_code | I1: failure_mode | J1: iso_fm_code_candidate (VERIFY) | K1: status | L1: source_subsystem | M1: linked_cases (count) | N1: failure_effect (from source) | O1: failure_cause (from source / case) | P1: corrective_action (from source)
A2: CP-PUMP-BRNG-01 | B2: MD-PUMP-BRNG-01-01 | C2: EQ-PUMP | D2: Centrifugal pump | E2: SS-PUMP-BRNG | F2: Bearing Assembly | G2: Rolling Element Bearing | H2: PUMP.BRNG.ROLL | I2: Bearing Wear | J2: VIB | K2: In taxonomy | L2: Bearing Assembly | M2: =COUNTIF(Case_Link!$E$2:$E$51,H2) -> 2 | N2: Local: rising vibration, noise and bearing temperature. Plant: shaft deflection damages seal, risk of seizure and unplanned pump trip. | O2: Contaminated or degraded grease; over/under-lubrication; misalignment; moisture ingress; bearing operated beyond rated life. | P2: Replace bearings as a set; inspect shaft journals and housing fits; regrease with specified grade and quantity; re-align coupling; trend vibration after restart.
A3: CP-PUMP-BRNG-02 | B3: MD-PUMP-BRNG-02-01 | C3: EQ-PUMP | D3: Centrifugal pump | E3: SS-PUMP-BRNG | F3: Bearing Assembly | G3: Bearing Housing Isolators / Lip Seals | H3: PUMP.BRNG.SEAL | I3: Bearing Housing Seal Failure | J3: ELU | K3: In taxonomy | L3: Bearing Assembly | M3: =COUNTIF(Case_Link!$E$2:$E$51,H3) -> 1 | N3: Local: oil leakage at shaft, contaminated lubricant. Plant: accelerated bearing failure and repeat lubricant top-ups. | O3: Seal wear from shaft runout; damaged shaft surface; overfilled oil level; blocked breather causing pressure build-up. | P3: Replace isolators or lip seals; inspect shaft surface; correct oil level; clean breather; change contaminated lubricant.
A4: CP-PUMP-SEAL-01 | B4: MD-PUMP-SEAL-01-01 | C4: EQ-PUMP | D4: Centrifugal pump | E4: SS-PUMP-SEAL | F4: Mechanical Seal | G4: Seal Faces (Rotating / Stationary) | H4: PUMP.SEAL.FACE | I4: Seal Face Leakage | J4: ELP | K4: In taxonomy | L4: Mechanical Seal | M4: =COUNTIF(Case_Link!$E$2:$E$51,H4) -> 2 | N4: Local: visible leakage at gland, wet baseplate. Plant: product loss, bearing contamination, safety and environmental exposure. | O4: Dry running; shaft deflection or excessive vibration; abrasive solids; elastomer incompatibility; incorrect installation or flush plan. | P4: Isolate and depressurise; replace seal faces and elastomers as a set; check shaft sleeve runout; verify flush/quench arrangement per seal plan.
A5: CP-PUMP-HYDR-01 | B5: MD-PUMP-HYDR-01-01 | C5: EQ-PUMP | D5: Centrifugal pump | E5: SS-PUMP-HYDR | F5: Hydraulic End | G5: Impeller | H5: PUMP.HYDR.IMPL | I5: Cavitation | J5: NOI | K5: In taxonomy | L5: Hydraulic End | M5: =COUNTIF(Case_Link!$E$2:$E$51,H5) -> 1 | N5: Local: gravel-like noise, vibration, pitted vanes. Plant: head and flow drop, shortened pump life, unstable process supply. | O5: NPSH available below NPSH required plus margin; blocked suction; excessive suction lift; high fluid temperature; throttled suction valve. | P5: Clear suction restriction; fully open suction valve; reduce lift or fluid temperature; verify NPSHa margin; repair or replace pitted impeller.
A6: CP-PUMP-HYDR-02 | B6: MD-PUMP-HYDR-02-01 | C6: EQ-PUMP | D6: Centrifugal pump | E6: SS-PUMP-HYDR | F6: Hydraulic End | G6: Impeller and Wear Rings | H6: PUMP.HYDR.WEAR | I6: Impeller / Wear Ring Wear | J6: LOO | K6: In taxonomy | L6: Hydraulic End | M6: =COUNTIF(Case_Link!$E$2:$E$51,H6) -> 1 | N6: Local: lower discharge pressure and flow at same motor current. Plant: process under-supply and higher energy per unit flow. | O6: Abrasive particles in fluid; corrosion; extended run without clearance check; prolonged operation away from best efficiency point. | P6: Measure wear-ring clearance against OEM limits; replace rings; replace or re-trim impeller; review fluid filtration.
A7: CP-PUMP-HYDR-03 | B7: MD-PUMP-HYDR-03-01 | C7: EQ-PUMP | D7: Centrifugal pump | E7: SS-PUMP-HYDR | F7: Hydraulic End | G7: Impeller and Casing Volute | H7: PUMP.HYDR.RECR | I7: Low-Flow Recirculation | J7: VIB | K7: In taxonomy | L7: Hydraulic End | M7: =COUNTIF(Case_Link!$E$2:$E$51,H7) -> 1 | N7: Local: noise, vibration, elevated temperature. Plant: reduced bearing/seal life and risk of damage if throttled for long periods. | O7: Excessive throttling; oversized pump; wrong operating point after process change; closed or blocked discharge. | P7: Restore operation within the allowable operating region; fit minimum-flow bypass; trim impeller or use variable speed drive; check discharge valve position.
A8: CP-PUMP-HYDR-04 | B8: MD-PUMP-HYDR-04-01 | C8: EQ-PUMP | D8: Centrifugal pump | E8: SS-PUMP-HYDR | F8: Hydraulic End | G8: Impeller Flow Passage | H8: PUMP.HYDR.BLKG | I8: Impeller Passage Blockage (Foreign Material) | J8: PLU | K8: Proposed (not approved) | L8: Hydraulic End | M8: =COUNTIF(Case_Link!$E$2:$E$51,H8) -> 1 | O8: Foreign material lodged in or near impeller, partially blocking vane passage (suspected, unconfirmed).
A9: CP-PUMP-HYDR-05 | B9: MD-PUMP-HYDR-05-01 | C9: EQ-PUMP | D9: Centrifugal pump | E9: SS-PUMP-HYDR | F9: Hydraulic End | G9: Pump-System Duty Point | H9: PUMP.HYDR.RNOT | I9: Operation Far Right of Duty Point (High-Flow Runout) | J9: HIO | K9: Proposed (not approved) | L9: Hydraulic End | M9: =COUNTIF(Case_Link!$E$2:$E$51,H9) -> 1 | O9: Pump operating far right of its duty point (high-flow runout) (suspected, unconfirmed).
A10: CP-PUMP-DRVT-01 | B10: MD-PUMP-DRVT-01-01 | C10: EQ-PUMP | D10: Centrifugal pump | E10: SS-PUMP-DRVT | F10: Drive Train | G10: Flexible Coupling | H10: PUMP.DRVT.CPLG | I10: Coupling Misalignment | J10: VIB | K10: In taxonomy | L10: Drive Train | M10: =COUNTIF(Case_Link!$E$2:$E$51,H10) -> 2 | N10: Local: 1x/2x running-speed vibration, coupling element wear, warm bearings. Plant: premature bearing and seal failures, repeat maintenance. | O10: Poor alignment at installation; thermal growth; soft foot; pipe strain; worn inserts; loose foundation bolts. | P10: Laser-align to tolerance with hot-alignment allowance; correct soft foot and pipe strain; replace worn coupling elements; retorque bolts.
A11: CP-PUMP-DRVT-02 | B11: MD-PUMP-DRVT-02-01 | C11: EQ-PUMP | D11: Centrifugal pump | E11: SS-PUMP-DRVT | F11: Drive Train | G11: Pump Rotating Assembly / Motor Protection | H11: PUMP.DRVT.OVLD | I11: Mechanical Overload or Binding Causing Protective Trip | J11: UST | K11: Proposed (not approved) | L11: Drive Train | M11: =COUNTIF(Case_Link!$E$2:$E$51,H11) -> 1 | O11: Mechanical overload from abnormal operating conditions or mechanical binding (suspected, unconfirmed).
A12: CP-PUMP-SUCT-01 | B12: MD-PUMP-SUCT-01-01 | C12: EQ-PUMP | D12: Centrifugal pump | E12: SS-PUMP-SUCT | F12: Suction System | G12: Suction Strainer | H12: PUMP.SUCT.STRN | I12: Strainer Blockage | J12: PLU | K12: In taxonomy | L12: Suction Line | M12: =COUNTIF(Case_Link!$E$2:$E$51,H12) -> 1 | N12: Local: high suction vacuum, noise, onset of cavitation. Plant: flow reduction and risk of dry running. | O12: Debris or scale in sump or line; no cleaning schedule; fouled tank; construction debris after outage. | P12: Isolate and clean or replace strainer; flush suction line; fit differential-pressure indication across strainer.
A13: CP-PUMP-SUCT-02 | B13: MD-PUMP-SUCT-02-01 | C13: EQ-PUMP | D13: Centrifugal pump | E13: SS-PUMP-SUCT | F13: Suction System | G13: Suction Line Joints and Gland Seal Interface | H13: PUMP.SUCT.PRIM | I13: Air Ingress / Loss of Prime | J13: LOO | K13: In taxonomy | L13: Suction and Priming | M13: =COUNTIF(Case_Link!$E$2:$E$51,H13) -> 2 | N13: Local: fluctuating or zero discharge pressure, noisy running. Plant: loss of delivery and dry-running damage to seal. | O13: Loose or damaged flange gaskets; low sump level or vortexing; suction valve stem leakage; incomplete priming or venting. | P13: Re-make suction joints; restore sump level; vent and prime per procedure; test suction line for air leaks before restart.
A14: CP-PUMP-SHFT-01 | B14: MD-PUMP-SHFT-01-01 | C14: EQ-PUMP | D14: Centrifugal pump | E14: SS-PUMP-SHFT | F14: Shaft Assembly | G14: Pump Shaft | H14: PUMP.SHFT.SHAF | I14: Shaft Fatigue Fracture | J14: STD | K14: In taxonomy | L14: Shaft Assembly | M14: =COUNTIF(Case_Link!$E$2:$E$51,H14) -> 1 | N14: Local: sudden loss of drive, severe vibration beforehand, seal destruction. Plant: unplanned outage and long-lead repair. | O14: Chronic misalignment or unbalance; operation far from best efficiency point; corrosion fatigue; poor fillet radii or fretting at sleeve. | P14: Replace shaft; inspect keyways and shoulders by NDT; correct alignment and operating range; review shaft material and corrosion protection.
A15: CP-MOT-STAT-01 | B15: MD-MOT-STAT-01-01 | C15: EQ-MOTOR | D15: Three-phase induction motor | E15: SS-MOT-STAT | F15: Stator and Windings | G15: Winding Insulation (Copper Magnet Wire and Varnish) | H15: ELEC.MOT.STAT | I15: Insulation Breakdown | J15: BRD | K15: In taxonomy | L15: Stator & Windings | M15: =COUNTIF(Case_Link!$E$2:$E$51,H15) -> 2 | N15: Local: low insulation resistance, burning smell, current imbalance. Plant: earth-fault or overcurrent trip and process stoppage. | O15: Overvoltage or voltage spikes (including inverter dv/dt); chronic overheating; moisture and dust ingress; repeated starts. | P15: Test insulation resistance and polarisation index; rewind or replace motor; remove moisture source; review protection and starting duty.
A16: CP-MOT-BRNG-01 | B16: MD-MOT-BRNG-01-01 | C16: EQ-MOTOR | D16: Three-phase induction motor | E16: SS-MOT-BRNG | F16: Bearing Assembly | G16: Drive-End Bearing and Grease | H16: ELEC.MOT.BRNG | I16: Bearing Overheating (Lubrication Failure) | J16: OHE | K16: In taxonomy | L16: Bearing Assembly | M16: =COUNTIF(Case_Link!$E$2:$E$51,H16) -> 2 | N16: Local: temperature rise, noise, discoloured grease. Plant: seizure, rotor-stator rub and motor trip. | O16: Wrong grease type or quantity; over-greasing; lubricant beyond service life; high ambient temperature; excessive belt tension. | P16: Clean and regrease with correct grade and quantity; replace damaged bearing; check belt or coupling load; revise relubrication interval.
A17: CP-MOT-BRNG-02 | B17: MD-MOT-BRNG-02-01 | C17: EQ-MOTOR | D17: Three-phase induction motor | E17: SS-MOT-BRNG | F17: Bearing Assembly | G17: Bearing (Inverter-Fed Shaft Currents) | H17: ELEC.MOT.BRDC | I17: Bearing Electrical Discharge Damage (Fluting) | J17: VIB | K17: In taxonomy | L17: Bearing Assembly | M17: =COUNTIF(Case_Link!$E$2:$E$51,H17) -> 1 | N17: Local: whining or growling noise, grey or fluted raceways. Plant: premature bearing failure on drive-fed motors. | O17: No shaft grounding or insulated bearing; poor drive cabling and earthing; high switching frequency. | P17: Fit insulated bearing or shaft-grounding ring; improve cable and earth bonding; replace bearing; review drive filtering.
A18: CP-MOT-ROTR-01 | B18: MD-MOT-ROTR-01-01 | C18: EQ-MOTOR | D18: Three-phase induction motor | E18: SS-MOT-ROTR | F18: Rotor Assembly | G18: Squirrel-Cage Rotor Bars and End Rings | H18: ELEC.MOT.ROTR | I18: Broken Rotor Bar | J18: VIB | K18: In taxonomy | L18: Rotor Assembly | M18: =COUNTIF(Case_Link!$E$2:$E$51,H18) -> 1 | N18: Local: speed fluctuation, pulsating current, current-spectrum sidebands, vibration. Plant: reduced torque and trip under load. | O18: Frequent direct-on-line starts; high-inertia load; casting defects; sustained overload. | P18: Confirm by motor current signature analysis; repair or replace rotor; review start frequency and loading.
A19: CP-MOT-ROTR-02 | B19: MD-MOT-ROTR-02-01 | C19: EQ-MOTOR | D19: Three-phase induction motor | E19: SS-MOT-ROTR | F19: Rotor Assembly | G19: Rotor Core and Shaft | H19: ELEC.MOT.IMBL | I19: Rotor Imbalance | J19: VIB | K19: In taxonomy | L19: Rotor Assembly | M19: =COUNTIF(Case_Link!$E$2:$E$51,H19) -> 1 | N19: Local: 1x running-speed vibration, bearing loading. Plant: reduced bearing life and coupling wear. | O19: Lost balance weights; fan damage; uneven dirt build-up; poor balance after repair. | P19: Balance rotor in situ or in shop to specified grade; clean rotor and fan; replace damaged parts; verify vibration after restart.
A20: CP-MOT-COOL-01 | B20: MD-MOT-COOL-01-01 | C20: EQ-MOTOR | D20: Three-phase induction motor | E20: SS-MOT-COOL | F20: Cooling System | G20: Cooling Fan and Cowl | H20: ELEC.MOT.COOL | I20: Cooling Airflow Blockage | J20: OHE | K20: In taxonomy | L20: Cooling System | M20: =COUNTIF(Case_Link!$E$2:$E$51,H20) -> 2 | N20: Local: casing and winding temperature rise. Plant: thermal overload trip and accelerated insulation ageing. | O20: Dust and lint build-up; damaged or loose fan; obstructed air inlet; high ambient temperature. | P20: Clean fins and cowl; replace damaged fan; clear obstructions; verify ambient temperature and ventilation.
A21: CP-MOT-TERM-01 | B21: MD-MOT-TERM-01-01 | C21: EQ-MOTOR | D21: Three-phase induction motor | E21: SS-MOT-TERM | F21: Terminal Box | G21: Terminal Lugs and Connections | H21: ELEC.MOT.TERM | I21: Loose Electrical Connection | J21: OHE | K21: In taxonomy | L21: Terminal Box | M21: =COUNTIF(Case_Link!$E$2:$E$51,H21) -> 1 | N21: Local: hot spots, discoloured lugs, current imbalance. Plant: overload trip and potential winding damage. | O21: Vibration-loosened bolts; poor crimping; oxidation or corrosion; cable overloading. | P21: De-energise and lock out; clean and retorque connections; replace damaged lugs; verify balanced phase currents.
A22: CP-MOT-MNTG-01 | B22: MD-MOT-MNTG-01-01 | C22: EQ-MOTOR | D22: Three-phase induction motor | E22: SS-MOT-MNTG | F22: Mounting and Foundation | G22: Motor Feet and Foundation Bolts | H22: ELEC.MOT.FEET | I22: Soft Foot / Mechanical Looseness | J22: VIB | K22: In taxonomy | L22: Mounting and Foundation | M22: =COUNTIF(Case_Link!$E$2:$E$51,H22) -> 1 | N22: Local: high 1x/2x vibration with directional differences. Plant: accelerated bearing wear and coupling damage. | O22: Loose or corroded bolts; uneven baseplate; cracked grout; incorrect shimming. | P22: Perform soft-foot check; shim and retorque; repair baseplate or grout; re-align to driven equipment.
A23: CP-MOT-SUPP-01 | B23: MD-MOT-SUPP-01-01 | C23: EQ-MOTOR | D23: Three-phase induction motor | E23: SS-MOT-SUPP | F23: Starter, Protection and Power Supply | G23: Supply Phase Conductors, Fuses and Contactor | H23: ELEC.MOT.SUPP | I23: Single-Phasing (Phase Loss) | J23: PDE | K23: In taxonomy | L23: Power Supply | M23: =COUNTIF(Case_Link!$E$2:$E$51,H23) -> 1 | N23: Local: humming, no start or reduced torque, high current in remaining phases. Plant: overload trip or winding burnout. | O23: Blown fuse; failed contactor pole; open conductor or loose lug; upstream supply fault. | P23: Isolate and trace the open phase; replace fuse/contactor contact; check winding insulation after event; verify phase-loss protection works.
A24: CP-MOT-SUPP-02 | B24: MD-MOT-SUPP-02-01 | C24: EQ-MOTOR | D24: Three-phase induction motor | E24: SS-MOT-SUPP | F24: Starter, Protection and Power Supply | G24: Thermal Overload Relay | H24: ELEC.MOT.STRT | I24: Overload Relay Trip Preventing Start | J24: FTS | K24: Proposed (not approved) | L24: Starter and Supply | M24: =COUNTIF(Case_Link!$E$2:$E$51,H24) -> 1 | O24: Overload relay tripped by sustained overcurrent or setting issue (suspected, unconfirmed).
A25: CP-MOT-SUPP-03 | B25: MD-MOT-SUPP-03-01 | C25: EQ-MOTOR | D25: Three-phase induction motor | E25: SS-MOT-SUPP | F25: Starter, Protection and Power Supply | G25: Overload Protection | H25: ELEC.MOT.OVLD | I25: Repeated Overload Trips from Excess Driven Load | J25: UST | K25: Proposed (not approved) | L25: Protection | M25: =COUNTIF(Case_Link!$E$2:$E$51,H25) -> 1 | O25: Excessive driven-equipment load (suspected, unconfirmed).
A26: CP-MOT-AGAP-01 | B26: MD-MOT-AGAP-01-01 | C26: EQ-MOTOR | D26: Three-phase induction motor | E26: SS-MOT-AGAP | F26: Rotor-Stator Interface (Air Gap) | G26: Air Gap (Rotor and Stator Core) | H26: ELEC.MOT.AGAP | I26: Air-Gap Eccentricity / Rotor-Stator Rub | J26: VIB | K26: In taxonomy | L26: Rotor-Stator Interface | M26: =COUNTIF(Case_Link!$E$2:$E$51,H26) -> 1 | N26: Local: vibration at twice line frequency, noise, core damage. Plant: motor failure and extended outage. | O26: Worn bearings; bent shaft; soft foot; assembly error after repair. | P26: Measure air gap; replace bearings; straighten or replace shaft; correct mounting; inspect core and windings for rub damage.
A27: CP-MOT-DRIV-01 | B27: MD-MOT-DRIV-01-01 | C27: EQ-MOTOR | D27: Three-phase induction motor | E27: SS-MOT-DRIV | F27: Drive and Speed Control (VFD) | G27: VFD Speed Feedback | H27: ELEC.MOT.VFDF | I27: Speed Feedback Signal Fault (Speed Fluctuation) | J27: ERO | K27: Proposed (not approved) | L27: Drive and Speed Control | M27: =COUNTIF(Case_Link!$E$2:$E$51,H27) -> 1 | O27: Faulty speed feedback signal (suspected, unconfirmed).
A28: CP-MOT-CPLG-01 | B28: MD-MOT-CPLG-01-01 | C28: EQ-MOTOR | D28: Three-phase induction motor | E28: SS-MOT-CPLG | F28: Coupling | G28: Motor-Load Coupling | H28: ELEC.MOT.CPLG | I28: Shaft Misalignment | J28: VIB | K28: Proposed (not approved) | L28: Coupling | M28: =COUNTIF(Case_Link!$E$2:$E$51,H28) -> 1 | O28: Shaft misalignment (suspected, unconfirmed).
A29: CP-COMP-AEND-01 | B29: MD-COMP-AEND-01-01 | C29: EQ-COMP | D29: Rotary screw air compressor | E29: SS-COMP-AEND | F29: Air End | G29: Rotor Screws (Male / Female) | H29: COMP.AEND.ROTR | I29: Rotor Wear / Clearance Increase | J29: LOO | K29: In taxonomy | L29: Air End | M29: =COUNTIF(Case_Link!$E$2:$E$51,H29) -> 1 | N29: Local: lower free-air delivery, higher discharge temperature and specific energy. Plant: loss of pressure and capacity. | O29: Dirty intake air; degraded or wrong oil; low oil level; extended service interval; bearing wear allowing rotor contact. | P29: Check oil quality and filtration; measure free-air delivery; overhaul or replace air end; correct oil and filter intervals.
A30: CP-COMP-AEND-02 | B30: MD-COMP-AEND-02-01 | C30: EQ-COMP | D30: Rotary screw air compressor | E30: SS-COMP-AEND | F30: Air End | G30: Air End Bearings | H30: COMP.AEND.BRNG | I30: Air End Bearing Failure | J30: VIB | K30: In taxonomy | L30: Air End | M30: =COUNTIF(Case_Link!$E$2:$E$51,H30) -> 1 | N30: Local: noise, vibration, rising discharge temperature. Plant: rotor contact, air end seizure, major overhaul. | O30: Contaminated or degraded oil; blocked oil filter; low oil flow; overpressure operation; long service interval. | P30: Replace bearings and set rotor clearances (or exchange air end); change oil and filter; investigate oil supply and filtration.
A31: CP-COMP-OSEP-01 | B31: MD-COMP-OSEP-01-01 | C31: EQ-COMP | D31: Rotary screw air compressor | E31: SS-COMP-OSEP | F31: Oil Separation and Air-Oil Circuit | G31: Oil Separator Element | H31: COMP.OSEP.ELEM | I31: Separator Element Clogging | J31: PLU | K31: In taxonomy | L31: Oil Separation System | M31: =COUNTIF(Case_Link!$E$2:$E$51,H31) -> 2 | N31: Local: high separator differential pressure and motor current. Plant: lower efficiency and oil carry-over if element fails. | O31: Service interval exceeded; varnished or degraded oil; poor intake filtration; high oil temperature. | P31: Replace separator element and oil filter; change oil if varnished; verify scavenge line and orifice are clear.
A32: CP-COMP-OSEP-02 | B32: MD-COMP-OSEP-02-01 | C32: EQ-COMP | D32: Rotary screw air compressor | E32: SS-COMP-OSEP | F32: Oil Separation and Air-Oil Circuit | G32: Minimum Pressure Valve | H32: COMP.VALV.MPV | I32: Minimum Pressure Valve Leakage / Sticking | J32: INL | K32: In taxonomy | L32: Air-Oil Circuit | M32: =COUNTIF(Case_Link!$E$2:$E$51,H32) -> 1 | N32: Local: slow pressure build-up, oil carry-over, irregular blowdown. Plant: reduced delivery and unstable operation. | O32: Worn seat or spring; varnish deposits; debris in valve. | P32: Clean or replace valve kit; verify opening pressure; check oil quality and separator condition.
A33: CP-COMP-INTK-01 | B33: MD-COMP-INTK-01-01 | C33: EQ-COMP | D33: Rotary screw air compressor | E33: SS-COMP-INTK | F33: Air Intake | G33: Intake Air Filter | H33: COMP.INTK.FILT | I33: Clogged Air Filter | J33: LOO | K33: In taxonomy | L33: Air Intake | M33: =COUNTIF(Case_Link!$E$2:$E$51,H33) -> 1 | N33: Local: reduced inlet pressure, lower capacity, higher temperature. Plant: loss of delivered air flow and pressure. | O33: Dusty environment; overdue replacement; damaged filter seal allowing bypass. | P33: Replace filter element; inspect housing seals; shorten replacement interval in dusty areas.
A34: CP-COMP-COOL-01 | B34: MD-COMP-COOL-01-01 | C34: EQ-COMP | D34: Rotary screw air compressor | E34: SS-COMP-COOL | F34: Cooling System | G34: Oil Cooler / Aftercooler | H34: COMP.COOL.COLR | I34: Cooler Fouling | J34: OHE | K34: In taxonomy | L34: Cooling System | M34: =COUNTIF(Case_Link!$E$2:$E$51,H34) -> 2 | N34: Local: high discharge air and oil temperature. Plant: high-temperature trip and accelerated oil degradation. | O34: Dirt on cooler core; blocked ventilation; high ambient temperature; failed cooling fan; low oil level. | P34: Clean cooler externally and internally; restore ventilation; check cooling fan; verify oil level and thermostatic valve.
A35: CP-COMP-CCTL-01 | B35: MD-COMP-CCTL-01-01 | C35: EQ-COMP | D35: Rotary screw air compressor | E35: SS-COMP-CCTL | F35: Capacity Control | G35: Inlet / Unloader Valve | H35: COMP.VALV.UNL | I35: Unloader Valve Sticking | J35: FTF | K35: In taxonomy | L35: Capacity Control | M35: =COUNTIF(Case_Link!$E$2:$E$51,H35) -> 1 | N35: Local: compressor stays loaded at set pressure or fails to build pressure. Plant: pressure swings, wasted energy, relief valve lifting. | O35: Worn seals or piston; dirt or varnish in valve; faults in control-air line. | P35: Strip and clean valve; replace seal kit; check control-air tubing; verify load and unload setpoints.
A36: CP-COMP-CCTL-02 | B36: MD-COMP-CCTL-02-01 | C36: EQ-COMP | D36: Rotary screw air compressor | E36: SS-COMP-CCTL | F36: Capacity Control | G36: Solenoid Valve (Load / Unload) | H36: COMP.VALV.SOL | I36: Solenoid Valve Failure | J36: FTF | K36: In taxonomy | L36: Capacity Control | M36: =COUNTIF(Case_Link!$E$2:$E$51,H36) -> 1 | N36: Local: compressor stays loaded or unloaded, frequent cycling or low pressure. Plant: unstable air supply and wasted energy. | O36: Coil failure; contaminated control air; worn plunger or seal; wiring fault. | P36: Check coil voltage and resistance; clean or replace valve; verify control-air quality; test load/unload sequence.
A37: CP-COMP-OILS-01 | B37: MD-COMP-OILS-01-01 | C37: EQ-COMP | D37: Rotary screw air compressor | E37: SS-COMP-OILS | F37: Oil System (Lubrication) | G37: Thermostatic (Temperature Control) Valve | H37: COMP.OILS.THRM | I37: Thermostatic Valve Sticking | J37: PDE | K37: In taxonomy | L37: Oil System | M37: =COUNTIF(Case_Link!$E$2:$E$51,H37) -> 1 | N37: Local: high discharge temperature if stuck closed to cooler; condensation in oil if stuck open. Plant: high-temperature trip or oil degradation. | O37: Wax element ageing; deposits or varnish; contaminated oil. | P37: Test and replace thermostatic element; clean valve body; change oil if contaminated.
A38: CP-COMP-CNDS-01 | B38: MD-COMP-CNDS-01-01 | C38: EQ-COMP | D38: Rotary screw air compressor | E38: SS-COMP-CNDS | F38: Condensate Management | G38: Automatic Condensate Drain | H38: COMP.COND.DRN | I38: Condensate Drain Blockage | J38: PLU | K38: In taxonomy | L38: Condensate Management | M38: =COUNTIF(Case_Link!$E$2:$E$51,H38) -> 1 | N38: Local: water accumulation in receiver and lines. Plant: moisture in downstream air, corrosion and tool or process contamination. | O38: Debris or rust in drain; failed solenoid or float; no routine drain check. | P38: Clean or replace drain valve and strainer; test drain function; add routine drain checks.
A39: CP-COMP-INST-01 | B39: MD-COMP-INST-01-01 | C39: EQ-COMP | D39: Rotary screw air compressor | E39: SS-COMP-INST | F39: Controls and Instrumentation | G39: Pressure Switch / Control Differential | H39: COMP.CTRL.PSET | I39: Incorrect Control Differential Setting (Frequent Cycling) | J39: SER | K39: Proposed (not approved) | L39: Pressure Control | M39: =COUNTIF(Case_Link!$E$2:$E$51,H39) -> 1 | O39: Incorrect control differential settings (suspected, unconfirmed).
A40: CP-COMP-INST-02 | B40: MD-COMP-INST-02-01 | C40: EQ-COMP | D40: Rotary screw air compressor | E40: SS-COMP-INST | F40: Controls and Instrumentation | G40: Pressure Sensor / Transmitter | H40: COMP.CTRL.PSEN | I40: Pressure Sensor Drift or Malfunction | J40: AIR | K40: Proposed (not approved) | L40: Controls and Instrumentation | M40: =COUNTIF(Case_Link!$E$2:$E$51,H40) -> 1 | O40: Pressure sensor drift/malfunction (suspected, unconfirmed).
...

Sheet Case_Link
A1: case_id | B1: equipment_class_id | C1: taxonomy_code_in_workbook | D1: taxonomy_code_proposed | E1: taxonomy_code_used | F1: mapping_status | G1: fm_id_vocab | H1: component_id (lookup) | I1: component_name (lookup)
A2: CASE-PUMP-001 | B2: EQ-PUMP | C2: PUMP.BRNG.ROLL | E2: =IF(C2<>"",C2,D2) -> PUMP.BRNG.ROLL | F2: MAPPED - cross-link provisional | G2: FM-051 | H2: =IFERROR(INDEX(Component_Map!$A$2:$A$42,MATCH(E2,Component_Map!$H$2:$H$42,0)),"UNMAPPED") -> CP-PUMP-BRNG-01 | I2: =IFERROR(INDEX(Component_Map!$G$2:$G$42,MATCH(E2,Component_Map!$H$2:$H$42,0)),"UNMAPPED") -> Rolling Element Bearing
A3: CASE-PUMP-002 | B3: EQ-PUMP | C3: PUMP.SEAL.FACE | E3: =IF(C3<>"",C3,D3) -> PUMP.SEAL.FACE | F3: MAPPED - cross-link provisional | G3: FM-032 | H3: =IFERROR(INDEX(Component_Map!$A$2:$A$42,MATCH(E3,Component_Map!$H$2:$H$42,0)),"UNMAPPED") -> CP-PUMP-SEAL-01 | I3: =IFERROR(INDEX(Component_Map!$G$2:$G$42,MATCH(E3,Component_Map!$H$2:$H$42,0)),"UNMAPPED") -> Seal Faces (Rotating / Stationary)
A4: CASE-PUMP-003 | B4: EQ-PUMP | C4: PUMP.DRVT.CPLG | E4: =IF(C4<>"",C4,D4) -> PUMP.DRVT.CPLG | F4: MAPPED - cross-link provisional | G4: FM-018 | H4: =IFERROR(INDEX(Component_Map!$A$2:$A$42,MATCH(E4,Component_Map!$H$2:$H$42,0)),"UNMAPPED") -> CP-PUMP-DRVT-01 | I4: =IFERROR(INDEX(Component_Map!$G$2:$G$42,MATCH(E4,Component_Map!$H$2:$H$42,0)),"UNMAPPED") -> Flexible Coupling
A5: CASE-PUMP-004 | B5: EQ-PUMP | C5: PUMP.SUCT.STRN | E5: =IF(C5<>"",C5,D5) -> PUMP.SUCT.STRN | F5: MAPPED - cross-link provisional | G5: FM-030 | H5: =IFERROR(INDEX(Component_Map!$A$2:$A$42,MATCH(E5,Component_Map!$H$2:$H$42,0)),"UNMAPPED") -> CP-PUMP-SUCT-01 | I5: =IFERROR(INDEX(Component_Map!$G$2:$G$42,MATCH(E5,Component_Map!$H$2:$H$42,0)),"UNMAPPED") -> Suction Strainer
A6: CASE-PUMP-005 | B6: EQ-PUMP | C6: PUMP.HYDR.IMPL | E6: =IF(C6<>"",C6,D6) -> PUMP.HYDR.IMPL | F6: MAPPED - cross-link provisional | G6: FM-003 | H6: =IFERROR(INDEX(Component_Map!$A$2:$A$42,MATCH(E6,Component_Map!$H$2:$H$42,0)),"UNMAPPED") -> CP-PUMP-HYDR-01 | I6: =IFERROR(INDEX(Component_Map!$G$2:$G$42,MATCH(E6,Component_Map!$H$2:$H$42,0)),"UNMAPPED") -> Impeller
A7: CASE-PUMP-006 | B7: EQ-PUMP | C7: PUMP.SEAL.FACE | E7: =IF(C7<>"",C7,D7) -> PUMP.SEAL.FACE | F7: AMBIGUOUS - expert review | G7: FM-032 | H7: =IFERROR(INDEX(Component_Map!$A$2:$A$42,MATCH(E7,Component_Map!$H$2:$H$42,0)),"UNMAPPED") -> CP-PUMP-SEAL-01 | I7: =IFERROR(INDEX(Component_Map!$G$2:$G$42,MATCH(E7,Component_Map!$H$2:$H$42,0)),"UNMAPPED") -> Seal Faces (Rotating / Stationary)
A8: CASE-PUMP-007 | B8: EQ-PUMP | C8: PUMP.BRNG.ROLL | E8: =IF(C8<>"",C8,D8) -> PUMP.BRNG.ROLL | F8: MAPPED - cross-link provisional | G8: FM-043 | H8: =IFERROR(INDEX(Component_Map!$A$2:$A$42,MATCH(E8,Component_Map!$H$2:$H$42,0)),"UNMAPPED") -> CP-PUMP-BRNG-01 | I8: =IFERROR(INDEX(Component_Map!$G$2:$G$42,MATCH(E8,Component_Map!$H$2:$H$42,0)),"UNMAPPED") -> Rolling Element Bearing
A9: CASE-PUMP-008 | B9: EQ-PUMP | C9: PUMP.SUCT.PRIM | E9: =IF(C9<>"",C9,D9) -> PUMP.SUCT.PRIM | F9: MAPPED - cross-link provisional | G9: FM-042 | H9: =IFERROR(INDEX(Component_Map!$A$2:$A$42,MATCH(E9,Component_Map!$H$2:$H$42,0)),"UNMAPPED") -> CP-PUMP-SUCT-02 | I9: =IFERROR(INDEX(Component_Map!$G$2:$G$42,MATCH(E9,Component_Map!$H$2:$H$42,0)),"UNMAPPED") -> Suction Line Joints and Gland Seal Interface
A10: CASE-PUMP-009 | B10: EQ-PUMP | C10: PUMP.BRNG.SEAL | E10: =IF(C10<>"",C10,D10) -> PUMP.BRNG.SEAL | F10: MAPPED - cross-link provisional | G10: FM-019 | H10: =IFERROR(INDEX(Component_Map!$A$2:$A$42,MATCH(E10,Component_Map!$H$2:$H$42,0)),"UNMAPPED") -> CP-PUMP-BRNG-02 | I10: =IFERROR(INDEX(Component_Map!$G$2:$G$42,MATCH(E10,Component_Map!$H$2:$H$42,0)),"UNMAPPED") -> Bearing Housing Isolators / Lip Seals
A11: CASE-PUMP-010 | B11: EQ-PUMP | D11: PUMP.HYDR.BLKG | E11: =IF(C11<>"",C11,D11) -> PUMP.HYDR.BLKG | F11: FM-ID ONLY - FMEA_Taxonomy gap | G11: FM-050 | H11: =IFERROR(INDEX(Component_Map!$A$2:$A$42,MATCH(E11,Component_Map!$H$2:$H$42,0)),"UNMAPPED") -> CP-PUMP-HYDR-04 | I11: =IFERROR(INDEX(Component_Map!$G$2:$G$42,MATCH(E11,Component_Map!$H$2:$H$42,0)),"UNMAPPED") -> Impeller Flow Passage
A12: CASE-PUMP-011 | B12: EQ-PUMP | D12: PUMP.HYDR.RNOT | E12: =IF(C12<>"",C12,D12) -> PUMP.HYDR.RNOT | F12: FM-ID ONLY - FMEA_Taxonomy gap | G12: FM-017 | H12: =IFERROR(INDEX(Component_Map!$A$2:$A$42,MATCH(E12,Component_Map!$H$2:$H$42,0)),"UNMAPPED") -> CP-PUMP-HYDR-05 | I12: =IFERROR(INDEX(Component_Map!$G$2:$G$42,MATCH(E12,Component_Map!$H$2:$H$42,0)),"UNMAPPED") -> Pump-System Duty Point
A13: CASE-PUMP-012 | B13: EQ-PUMP | D13: PUMP.DRVT.OVLD | E13: =IF(C13<>"",C13,D13) -> PUMP.DRVT.OVLD | F13: FM-ID ONLY - FMEA_Taxonomy gap | G13: FM-048 | H13: =IFERROR(INDEX(Component_Map!$A$2:$A$42,MATCH(E13,Component_Map!$H$2:$H$42,0)),"UNMAPPED") -> CP-PUMP-DRVT-02 | I13: =IFERROR(INDEX(Component_Map!$G$2:$G$42,MATCH(E13,Component_Map!$H$2:$H$42,0)),"UNMAPPED") -> Pump Rotating Assembly / Motor Protection
A14: CASE-PUMP-013 | B14: EQ-PUMP | C14: PUMP.HYDR.WEAR | E14: =IF(C14<>"",C14,D14) -> PUMP.HYDR.WEAR | F14: AMBIGUOUS - expert review | G14: FM-030 | H14: =IFERROR(INDEX(Component_Map!$A$2:$A$42,MATCH(E14,Component_Map!$H$2:$H$42,0)),"UNMAPPED") -> CP-PUMP-HYDR-02 | I14: =IFERROR(INDEX(Component_Map!$G$2:$G$42,MATCH(E14,Component_Map!$H$2:$H$42,0)),"UNMAPPED") -> Impeller and Wear Rings
A15: CASE-PUMP-014 | B15: EQ-PUMP | C15: PUMP.DRVT.CPLG | E15: =IF(C15<>"",C15,D15) -> PUMP.DRVT.CPLG | F15: AMBIGUOUS - expert review | G15: FM-018 | H15: =IFERROR(INDEX(Component_Map!$A$2:$A$42,MATCH(E15,Component_Map!$H$2:$H$42,0)),"UNMAPPED") -> CP-PUMP-DRVT-01 | I15: =IFERROR(INDEX(Component_Map!$G$2:$G$42,MATCH(E15,Component_Map!$H$2:$H$42,0)),"UNMAPPED") -> Flexible Coupling
A16: CASE-PUMP-015 | B16: EQ-PUMP | C16: PUMP.HYDR.RECR | E16: =IF(C16<>"",C16,D16) -> PUMP.HYDR.RECR | F16: AMBIGUOUS - expert review | G16: FM-018 | H16: =IFERROR(INDEX(Component_Map!$A$2:$A$42,MATCH(E16,Component_Map!$H$2:$H$42,0)),"UNMAPPED") -> CP-PUMP-HYDR-03 | I16: =IFERROR(INDEX(Component_Map!$G$2:$G$42,MATCH(E16,Component_Map!$H$2:$H$42,0)),"UNMAPPED") -> Impeller and Casing Volute
A17: CASE-PUMP-016 | B17: EQ-PUMP | C17: PUMP.SUCT.PRIM | E17: =IF(C17<>"",C17,D17) -> PUMP.SUCT.PRIM | F17: AMBIGUOUS - expert review | G17: FM-030 | H17: =IFERROR(INDEX(Component_Map!$A$2:$A$42,MATCH(E17,Component_Map!$H$2:$H$42,0)),"UNMAPPED") -> CP-PUMP-SUCT-02 | I17: =IFERROR(INDEX(Component_Map!$G$2:$G$42,MATCH(E17,Component_Map!$H$2:$H$42,0)),"UNMAPPED") -> Suction Line Joints and Gland Seal Interface
A18: CASE-PUMP-017 | B18: EQ-PUMP | C18: PUMP.SHFT.SHAF | E18: =IF(C18<>"",C18,D18) -> PUMP.SHFT.SHAF | F18: AMBIGUOUS - expert review | G18: FM-042 | H18: =IFERROR(INDEX(Component_Map!$A$2:$A$42,MATCH(E18,Component_Map!$H$2:$H$42,0)),"UNMAPPED") -> CP-PUMP-SHFT-01 | I18: =IFERROR(INDEX(Component_Map!$G$2:$G$42,MATCH(E18,Component_Map!$H$2:$H$42,0)),"UNMAPPED") -> Pump Shaft
A19: CASE-MOT-001 | B19: EQ-MOTOR | C19: ELEC.MOT.STAT | E19: =IF(C19<>"",C19,D19) -> ELEC.MOT.STAT | F19: MAPPED - cross-link provisional | G19: FM-028 | H19: =IFERROR(INDEX(Component_Map!$A$2:$A$42,MATCH(E19,Component_Map!$H$2:$H$42,0)),"UNMAPPED") -> CP-MOT-STAT-01 | I19: =IFERROR(INDEX(Component_Map!$G$2:$G$42,MATCH(E19,Component_Map!$H$2:$H$42,0)),"UNMAPPED") -> Winding Insulation (Copper Magnet Wire and Varnish)
A20: CASE-MOT-002 | B20: EQ-MOTOR | C20: ELEC.MOT.BRNG | E20: =IF(C20<>"",C20,D20) -> ELEC.MOT.BRNG | F20: MAPPED - cross-link provisional | G20: FM-035 | H20: =IFERROR(INDEX(Component_Map!$A$2:$A$42,MATCH(E20,Component_Map!$H$2:$H$42,0)),"UNMAPPED") -> CP-MOT-BRNG-01 | I20: =IFERROR(INDEX(Component_Map!$G$2:$G$42,MATCH(E20,Component_Map!$H$2:$H$42,0)),"UNMAPPED") -> Drive-End Bearing and Grease
A21: CASE-MOT-003 | B21: EQ-MOTOR | C21: ELEC.MOT.COOL | E21: =IF(C21<>"",C21,D21) -> ELEC.MOT.COOL | F21: MAPPED - cross-link provisional | G21: FM-039 | H21: =IFERROR(INDEX(Component_Map!$A$2:$A$42,MATCH(E21,Component_Map!$H$2:$H$42,0)),"UNMAPPED") -> CP-MOT-COOL-01 | I21: =IFERROR(INDEX(Component_Map!$G$2:$G$42,MATCH(E21,Component_Map!$H$2:$H$42,0)),"UNMAPPED") -> Cooling Fan and Cowl
A22: CASE-MOT-004 | B22: EQ-MOTOR | D22: ELEC.MOT.STRT | E22: =IF(C22<>"",C22,D22) -> ELEC.MOT.STRT | F22: FM-ID ONLY - FMEA_Taxonomy gap | G22: FM-037 | H22: =IFERROR(INDEX(Component_Map!$A$2:$A$42,MATCH(E22,Component_Map!$H$2:$H$42,0)),"UNMAPPED") -> CP-MOT-SUPP-02 | I22: =IFERROR(INDEX(Component_Map!$G$2:$G$42,MATCH(E22,Component_Map!$H$2:$H$42,0)),"UNMAPPED") -> Thermal Overload Relay
A23: CASE-MOT-005 | B23: EQ-MOTOR | C23: ELEC.MOT.IMBL | E23: =IF(C23<>"",C23,D23) -> ELEC.MOT.IMBL | F23: MAPPED - cross-link provisional | G23: FM-036 | H23: =IFERROR(INDEX(Component_Map!$A$2:$A$42,MATCH(E23,Component_Map!$H$2:$H$42,0)),"UNMAPPED") -> CP-MOT-ROTR-02 | I23: =IFERROR(INDEX(Component_Map!$G$2:$G$42,MATCH(E23,Component_Map!$H$2:$H$42,0)),"UNMAPPED") -> Rotor Core and Shaft
A24: CASE-MOT-006 | B24: EQ-MOTOR | C24: ELEC.MOT.BRNG | E24: =IF(C24<>"",C24,D24) -> ELEC.MOT.BRNG | F24: MAPPED - cross-link provisional | G24: FM-035 | H24: =IFERROR(INDEX(Component_Map!$A$2:$A$42,MATCH(E24,Component_Map!$H$2:$H$42,0)),"UNMAPPED") -> CP-MOT-BRNG-01 | I24: =IFERROR(INDEX(Component_Map!$G$2:$G$42,MATCH(E24,Component_Map!$H$2:$H$42,0)),"UNMAPPED") -> Drive-End Bearing and Grease
A25: CASE-MOT-007 | B25: EQ-MOTOR | D25: ELEC.MOT.OVLD | E25: =IF(C25<>"",C25,D25) -> ELEC.MOT.OVLD | F25: FM-ID ONLY - FMEA_Taxonomy gap | G25: FM-047 | H25: =IFERROR(INDEX(Component_Map!$A$2:$A$42,MATCH(E25,Component_Map!$H$2:$H$42,0)),"UNMAPPED") -> CP-MOT-SUPP-03 | I25: =IFERROR(INDEX(Component_Map!$G$2:$G$42,MATCH(E25,Component_Map!$H$2:$H$42,0)),"UNMAPPED") -> Overload Protection
A26: CASE-MOT-008 | B26: EQ-MOTOR | C26: ELEC.MOT.SUPP | E26: =IF(C26<>"",C26,D26) -> ELEC.MOT.SUPP | F26: MAPPED - cross-link provisional | G26: FM-038 | H26: =IFERROR(INDEX(Component_Map!$A$2:$A$42,MATCH(E26,Component_Map!$H$2:$H$42,0)),"UNMAPPED") -> CP-MOT-SUPP-01 | I26: =IFERROR(INDEX(Component_Map!$G$2:$G$42,MATCH(E26,Component_Map!$H$2:$H$42,0)),"UNMAPPED") -> Supply Phase Conductors, Fuses and Contactor
A27: CASE-MOT-009 | B27: EQ-MOTOR | C27: ELEC.MOT.STAT | E27: =IF(C27<>"",C27,D27) -> ELEC.MOT.STAT | F27: MAPPED - cross-link provisional | G27: FM-028 | H27: =IFERROR(INDEX(Component_Map!$A$2:$A$42,MATCH(E27,Component_Map!$H$2:$H$42,0)),"UNMAPPED") -> CP-MOT-STAT-01 | I27: =IFERROR(INDEX(Component_Map!$G$2:$G$42,MATCH(E27,Component_Map!$H$2:$H$42,0)),"UNMAPPED") -> Winding Insulation (Copper Magnet Wire and Varnish)
A28: CASE-MOT-010 | B28: EQ-MOTOR | D28: ELEC.MOT.VFDF | E28: =IF(C28<>"",C28,D28) -> ELEC.MOT.VFDF | F28: FM-ID ONLY - FMEA_Taxonomy gap | G28: FM-041 | H28: =IFERROR(INDEX(Component_Map!$A$2:$A$42,MATCH(E28,Component_Map!$H$2:$H$42,0)),"UNMAPPED") -> CP-MOT-DRIV-01 | I28: =IFERROR(INDEX(Component_Map!$G$2:$G$42,MATCH(E28,Component_Map!$H$2:$H$42,0)),"UNMAPPED") -> VFD Speed Feedback
A29: CASE-MOT-011 | B29: EQ-MOTOR | C29: ELEC.MOT.TERM | E29: =IF(C29<>"",C29,D29) -> ELEC.MOT.TERM | F29: MAPPED - cross-link provisional | G29: FM-040 | H29: =IFERROR(INDEX(Component_Map!$A$2:$A$42,MATCH(E29,Component_Map!$H$2:$H$42,0)),"UNMAPPED") -> CP-MOT-TERM-01 | I29: =IFERROR(INDEX(Component_Map!$G$2:$G$42,MATCH(E29,Component_Map!$H$2:$H$42,0)),"UNMAPPED") -> Terminal Lugs and Connections
A30: CASE-MOT-012 | B30: EQ-MOTOR | C30: ELEC.MOT.COOL | E30: =IF(C30<>"",C30,D30) -> ELEC.MOT.COOL | F30: AMBIGUOUS - expert review | G30: FM-034 | H30: =IFERROR(INDEX(Component_Map!$A$2:$A$42,MATCH(E30,Component_Map!$H$2:$H$42,0)),"UNMAPPED") -> CP-MOT-COOL-01 | I30: =IFERROR(INDEX(Component_Map!$G$2:$G$42,MATCH(E30,Component_Map!$H$2:$H$42,0)),"UNMAPPED") -> Cooling Fan and Cowl
A31: CASE-MOT-013 | B31: EQ-MOTOR | C31: ELEC.MOT.FEET | E31: =IF(C31<>"",C31,D31) -> ELEC.MOT.FEET | F31: MAPPED - cross-link provisional | G31: FM-036 | H31: =IFERROR(INDEX(Component_Map!$A$2:$A$42,MATCH(E31,Component_Map!$H$2:$H$42,0)),"UNMAPPED") -> CP-MOT-MNTG-01 | I31: =IFERROR(INDEX(Component_Map!$G$2:$G$42,MATCH(E31,Component_Map!$H$2:$H$42,0)),"UNMAPPED") -> Motor Feet and Foundation Bolts
A32: CASE-MOT-014 | B32: EQ-MOTOR | C32: ELEC.MOT.AGAP | E32: =IF(C32<>"",C32,D32) -> ELEC.MOT.AGAP | F32: AMBIGUOUS - expert review | G32: FM-034 | H32: =IFERROR(INDEX(Component_Map!$A$2:$A$42,MATCH(E32,Component_Map!$H$2:$H$42,0)),"UNMAPPED") -> CP-MOT-AGAP-01 | I32: =IFERROR(INDEX(Component_Map!$G$2:$G$42,MATCH(E32,Component_Map!$H$2:$H$42,0)),"UNMAPPED") -> Air Gap (Rotor and Stator Core)
A33: CASE-MOT-015 | B33: EQ-MOTOR | C33: ELEC.MOT.ROTR | E33: =IF(C33<>"",C33,D33) -> ELEC.MOT.ROTR | F33: AMBIGUOUS - expert review | G33: FM-036 | H33: =IFERROR(INDEX(Component_Map!$A$2:$A$42,MATCH(E33,Component_Map!$H$2:$H$42,0)),"UNMAPPED") -> CP-MOT-ROTR-01 | I33: =IFERROR(INDEX(Component_Map!$G$2:$G$42,MATCH(E33,Component_Map!$H$2:$H$42,0)),"UNMAPPED") -> Squirrel-Cage Rotor Bars and End Rings
A34: CASE-MOT-016 | B34: EQ-MOTOR | C34: ELEC.MOT.BRDC | E34: =IF(C34<>"",C34,D34) -> ELEC.MOT.BRDC | F34: AMBIGUOUS - expert review | G34: FM-034 | H34: =IFERROR(INDEX(Component_Map!$A$2:$A$42,MATCH(E34,Component_Map!$H$2:$H$42,0)),"UNMAPPED") -> CP-MOT-BRNG-02 | I34: =IFERROR(INDEX(Component_Map!$G$2:$G$42,MATCH(E34,Component_Map!$H$2:$H$42,0)),"UNMAPPED") -> Bearing (Inverter-Fed Shaft Currents)
A35: CASE-MOT-017 | B35: EQ-MOTOR | D35: ELEC.MOT.CPLG | E35: =IF(C35<>"",C35,D35) -> ELEC.MOT.CPLG | F35: FM-ID ONLY - FMEA_Taxonomy gap | G35: FM-036 | H35: =IFERROR(INDEX(Component_Map!$A$2:$A$42,MATCH(E35,Component_Map!$H$2:$H$42,0)),"UNMAPPED") -> CP-MOT-CPLG-01 | I35: =IFERROR(INDEX(Component_Map!$G$2:$G$42,MATCH(E35,Component_Map!$H$2:$H$42,0)),"UNMAPPED") -> Motor-Load Coupling
A36: CASE-COMP-001 | B36: EQ-COMP | C36: COMP.OSEP.ELEM | E36: =IF(C36<>"",C36,D36) -> COMP.OSEP.ELEM | F36: MAPPED - cross-link provisional | G36: FM-029 | H36: =IFERROR(INDEX(Component_Map!$A$2:$A$42,MATCH(E36,Component_Map!$H$2:$H$42,0)),"UNMAPPED") -> CP-COMP-OSEP-01 | I36: =IFERROR(INDEX(Component_Map!$G$2:$G$42,MATCH(E36,Component_Map!$H$2:$H$42,0)),"UNMAPPED") -> Oil Separator Element
A37: CASE-COMP-002 | B37: EQ-COMP | C37: COMP.COOL.COLR | E37: =IF(C37<>"",C37,D37) -> COMP.COOL.COLR | F37: MAPPED - cross-link provisional | G37: FM-005 | H37: =IFERROR(INDEX(Component_Map!$A$2:$A$42,MATCH(E37,Component_Map!$H$2:$H$42,0)),"UNMAPPED") -> CP-COMP-COOL-01 | I37: =IFERROR(INDEX(Component_Map!$G$2:$G$42,MATCH(E37,Component_Map!$H$2:$H$42,0)),"UNMAPPED") -> Oil Cooler / Aftercooler
A38: CASE-COMP-003 | B38: EQ-COMP | C38: COMP.COOL.COLR | E38: =IF(C38<>"",C38,D38) -> COMP.COOL.COLR | F38: MAPPED - cross-link provisional | G38: FM-005 | H38: =IFERROR(INDEX(Component_Map!$A$2:$A$42,MATCH(E38,Component_Map!$H$2:$H$42,0)),"UNMAPPED") -> CP-COMP-COOL-01 | I38: =IFERROR(INDEX(Component_Map!$G$2:$G$42,MATCH(E38,Component_Map!$H$2:$H$42,0)),"UNMAPPED") -> Oil Cooler / Aftercooler
A39: CASE-COMP-004 | B39: EQ-COMP | C39: COMP.INTK.FILT | E39: =IF(C39<>"",C39,D39) -> COMP.INTK.FILT | F39: MAPPED - cross-link provisional | G39: FM-029 | H39: =IFERROR(INDEX(Component_Map!$A$2:$A$42,MATCH(E39,Component_Map!$H$2:$H$42,0)),"UNMAPPED") -> CP-COMP-INTK-01 | I39: =IFERROR(INDEX(Component_Map!$G$2:$G$42,MATCH(E39,Component_Map!$H$2:$H$42,0)),"UNMAPPED") -> Intake Air Filter
A40: CASE-COMP-005 | B40: EQ-COMP | C40: COMP.OSEP.ELEM | E40: =IF(C40<>"",C40,D40) -> COMP.OSEP.ELEM | F40: AMBIGUOUS - expert review | G40: FM-016 | H40: =IFERROR(INDEX(Component_Map!$A$2:$A$42,MATCH(E40,Component_Map!$H$2:$H$42,0)),"UNMAPPED") -> CP-COMP-OSEP-01 | I40: =IFERROR(INDEX(Component_Map!$G$2:$G$42,MATCH(E40,Component_Map!$H$2:$H$42,0)),"UNMAPPED") -> Oil Separator Element
...

Sheet Open_Issues
A1: # | B1: Issue | C1: Why it matters | D1: What this workbook currently assumes | E1: Suggested owner | F1: Status
A2: 1 | B2: Class vs type | C2: The source workbook calls 'Centrifugal Pump' a class. In ISO 14224 terms the class is Pump and centrifugal is a type. Cases use equipment_class_id = EQ-PUMP etc. | D2: Adds a type level (TY-...). EQ-xxx IDs unchanged, so nothing in Import_View breaks. Class names become Pump / Electric Motor / Compressor. | E2: M01 / Group 2 | F2: OPEN
A3: 2 | B3: Subsystem merges | C3: Source subsystems overlap: pump Suction Line vs Suction and Priming; motor Power Supply vs Starter and Supply vs Protection; compressor Oil Separation System vs Air-Oil Circuit; compressor Pressure Control vs Controls and Instrumentation. | D3: Merged in the Hierarchy; the original names stay in source_subsystem so the merge can be reversed. | E3: M01 / M02 | F3: OPEN
A4: 3 | B4: Taxonomy code pattern | C4: Pump and compressor codes are CLASS.SUBSYSTEM.COMPONENT (PUMP.BRNG.ROLL). Motor codes are ELEC.MOT.<x> and do not carry the subsystem consistently. Group 2 will use codes as keys and Group 3 as filters. | D4: Codes left exactly as in the source. New node IDs follow one uniform pattern. A rename would need Group 2 and 3 agreement. | E4: Group 2 / M01 | F4: OPEN
A5: 4 | B5: Composite component names | C5: Some components bundle several parts: 'Impeller and Wear Rings', 'Impeller and Casing Volute', 'Suction Line Joints and Gland Seal Interface', 'Rotor Core and Shaft'. A component with several parts makes filtering ambiguous. | D5: Kept as in source. Recommendation: split into atomic components (Impeller, Wear Rings, Casing/Volute, ...) and point each failure mode at one. | E5: M01 / M02 | F5: OPEN
A6: 5 | B6: Equipment boundary (pump vs driver) | C6: Proposed CASE-PUMP-012 puts motor overload protection under the pump Drive Train. In ISO terms the driver is separate equipment. CASE-PUMP-011 (high-flow run-out) describes an operating point, not a component. | D6: Both kept as proposed rows, flagged. Suggest moving PUMP-012 to the motor Starter/Protection subsystem and treating PUMP-011 as an operating-condition tag or a mode on the Impeller. | E6: M01 / M03 | F6: OPEN
A7: 6 | B7: Overlap of MOT-004 and MOT-007 | C7: Both describe an overload-relay trip. They are symptoms more than failure modes. | D7: Both kept under Starter, Protection and Power Supply as proposed rows. | E7: M02 | F7: OPEN
A8: 7 | B8: Motor bearing component name | C8: 'Drive-End Bearing and Grease' is linked to CASE-MOT-002, whose symptom is the non-drive end. The name is too specific. | D8: Unchanged. Suggest 'Motor Bearings and Grease (DE/NDE)'. | E8: M03 | F8: OPEN
A9: 8 | B9: ISO failure-mode codes not verified | C9: iso_fm_code_candidate values (VIB, OHE, PLU, ...) come from the source workbook and Taxonomy_Proposed. The ISO 14224 full text has not been inspected and the codes are class-specific. | D9: Shown as candidates only. Do not publish as ISO codes until M01 checks Annex B. | E9: M01 | F9: OPEN
A10: 9 | B10: Failure mode vs symptom vs FM-xxx vocabulary | C10: Project-local FM-xxx IDs are not ISO codes and several are symptoms, not failure modes. 13 mappings are AMBIGUOUS and 11 cases have no taxonomy entry. | D10: Hierarchy uses its own MD- IDs and does not replace FM-xxx. Case_Link carries fm_id_vocab for reference. | E10: M01 / M02 / Group 2 | F10: OPEN
